Workbook

Sheet Test Plan
A1: Test Plan - Sauce Demo UI & Users API Automation
A3: Document information
A4: Version | B4: 1.0
A5: Date | B5: 2026-10-12
A6: Prepared by
A7: Reviewed / approved by
A8: 1. Objective
A9: Objective | B9: Verify the core user journeys of the Sauce Demo web shop (login, cart, checkout, purchase) and the reqres.in Users API, using an automated Cucumber (BDD) regression suite that can be run on demand against the qa or staging environment.
A10: 2. Scope
A11: In scope | B11: - Login: valid, invalid, locked-out and data-driven (Excel) credentials - Products page: sorting by price, adding items to the cart, cart badge - Cart: contents, removing items, proceeding to checkout - Checkout: required-field validation, cancelling, order overview totals (item total and tax), order completion - Logout - Browser window/tab handling after login - Users API: get single user, list users, create user, unknown user (404)
A12: Out of scope | B12: - Performance, load and security testing - Accessibility and visual/layout testing - Mobile browsers and browsers other than Chrome and Firefox - Real payment processing (Sauce Demo has none) - Other reqres.in resources and authenticated API endpoints beyond the login token flow
A13: 3. Applications under test
A14: Web UI | B14: Sauce Demo - https://www.saucedemo.com (public demo shop)
A15: API | B15: reqres.in - https://reqres.in/api (public demo REST API)
A16: 4. Test approach
A17: Methodology | B17: Behaviour-driven: each scenario is written in Gherkin (.feature files) and mapped to step definitions. Every scenario name starts with its test case ID so results in logs and reports trace back to this workbook.
A18: Test types | B18: - Functional positive - Negative (invalid input, validation errors) - Data-driven (Excel test data) - End-to-end (full purchase journey) - API (status codes, response fields)
A19: Automation | B19: Selenium WebDriver 4 (UI) and RestAssured 5 (API), run by Cucumber 7 on the JUnit Platform with Maven. All test cases on the Test Cases sheet are automated. New cases can be added as 'Not automated' and executed manually until they are automated.
A20: Regression | B20: The full suite (tag @All) runs on every change. Smaller subsets can be run by tag, e.g. @smoke, @e2e, @API.
A21: 5. Test environment
A22: Environments | B22: qa (default) and staging, selected with -Denv=<name>. Configuration lives in src/test/resources/config/.
A23: Browsers | B23: Chrome (default) and Firefox, selected with -Dbrowser=<name>. Headless mode with -Dheadless=true.
A24: Tooling | B24: Java 21, Maven 3.9+, Selenium 4.48, Cucumber 7.34, RestAssured 5.5, ExtentReports 5.1, Log4j2.
A25: 6. Test data
A26: Sources | B26: - Excel: src/test/resources/testdata/<env>/TestData.xlsx (sheet 'Login', keyed by TestDataId) - JSON request bodies: src/test/resources/testdata/api/ - Inline values in feature files (Examples tables)
A27: Accounts | B27: Sauce Demo public demo accounts (e.g. standard_user / secret_sauce, locked_out_user). reqres.in demo credentials from config.properties. No production or personal data is used.
A28: 7. Entry criteria
A29: Entry | B29: - Test environment URLs reachable - Build compiles (mvn test-compile) - Test data available for the selected environment - Browser installed for UI runs
A30: 8. Exit criteria
A31: Exit | B31: - 100% of automated test cases executed - All Critical and High priority test cases passed - No open Critical or High severity defects - Execution results recorded on the Test Cases sheet and reports archived
A32: 9. Suspension / resumption
A33: Suspend when | B33: The application under test or reqres.in is unavailable, or a blocking defect stops the login or checkout flow.
A34: Resume when | B34: The environment is available again or the blocking defect is fixed and verified.
A35: 10. Risks and mitigations
A36: Third-party demo sites | B36: Both systems under test are public demo sites outside our control; outages or content changes cause failures unrelated to our code. Mitigation: re-run failed cases, check the site manually before raising a defect.
A37: API rate limiting | B37: reqres.in allows 40 requests per day per IP address without an account (plus a 20 requests/minute window). When the limit is used up, API cases fail with 429 'rate_limit_exceeded' until midnight UTC. Mitigation: avoid repeated API runs, run API tests once per cycle with -Dcucumber.filter.tags=@API, or use a reqres.in account for a higher limit.
A38: Browser / driver drift | B38: Newer Chrome versions than Selenium supports produce CDP warnings and could break features. Mitigation: keep Selenium up to date.
A39: Browser popups | B39: Chrome's password-breach dialog blocks UI tests after login. Mitigation: the password manager is disabled in ChromeDriverImpl.
A40: Locator changes | B40: UI changes can break element locators. Mitigation: locators use stable data-test attributes where available and live only in page objects.
A41: 11. Deliverables
...

Sheet Summary
A1: Execution Summary
A2: All figures are calculated from the Test Cases sheet.
A3: Metric | B3: Value
A4: Total test cases | B4: =COUNTA('Test Cases'!$A:$A)-1 -> 19
A5: Automated | B5: =COUNTIF('Test Cases'!$K:$K,"Automated") -> 19
A6: Not automated (proposed) | B6: =COUNTIF('Test Cases'!$K:$K,"Not automated") -> 0
A7: Automation coverage | B7: =IF(B4=0,0,B5/B4) -> 1
A8: Passed | B8: =COUNTIF('Test Cases'!$O:$O,"Pass") -> 19
A9: Failed | B9: =COUNTIF('Test Cases'!$O:$O,"Fail") -> 0
A10: Blocked | B10: =COUNTIF('Test Cases'!$O:$O,"Blocked") -> 0
A11: Not run | B11: =COUNTIF('Test Cases'!$O:$O,"Not Run") -> 0
A12: Executed | B12: =B8+B9+B10 -> 19
A13: Pass rate (of executed) | B13: =IF(B12=0,0,B8/B12) -> 1
A15: By module
A16: Module | B16: Test Cases | C16: Automated | D16: Passed | E16: Failed | F16: Blocked | G16: Not Run
A17: Login | B17: =COUNTIF('Test Cases'!$C:$C,A17) -> 6 | C17: =COUNTIFS('Test Cases'!$C:$C,A17,'Test Cases'!$K:$K,"Automated") -> 6 | D17: =COUNTIFS('Test Cases'!$C:$C,A17,'Test Cases'!$O:$O,"Pass") -> 6 | E17: =COUNTIFS('Test Cases'!$C:$C,A17,'Test Cases'!$O:$O,"Fail") -> 0 | F17: =COUNTIFS('Test Cases'!$C:$C,A17,'Test Cases'!$O:$O,"Blocked") -> 0 | G17: =COUNTIFS('Test Cases'!$C:$C,A17,'Test Cases'!$O:$O,"Not Run") -> 0
A18: Browser windows | B18: =COUNTIF('Test Cases'!$C:$C,A18) -> 1 | C18: =COUNTIFS('Test Cases'!$C:$C,A18,'Test Cases'!$K:$K,"Automated") -> 1 | D18: =COUNTIFS('Test Cases'!$C:$C,A18,'Test Cases'!$O:$O,"Pass") -> 1 | E18: =COUNTIFS('Test Cases'!$C:$C,A18,'Test Cases'!$O:$O,"Fail") -> 0 | F18: =COUNTIFS('Test Cases'!$C:$C,A18,'Test Cases'!$O:$O,"Blocked") -> 0 | G18: =COUNTIFS('Test Cases'!$C:$C,A18,'Test Cases'!$O:$O,"Not Run") -> 0
A19: Products | B19: =COUNTIF('Test Cases'!$C:$C,A19) -> 1 | C19: =COUNTIFS('Test Cases'!$C:$C,A19,'Test Cases'!$K:$K,"Automated") -> 1 | D19: =COUNTIFS('Test Cases'!$C:$C,A19,'Test Cases'!$O:$O,"Pass") -> 1 | E19: =COUNTIFS('Test Cases'!$C:$C,A19,'Test Cases'!$O:$O,"Fail") -> 0 | F19: =COUNTIFS('Test Cases'!$C:$C,A19,'Test Cases'!$O:$O,"Blocked") -> 0 | G19: =COUNTIFS('Test Cases'!$C:$C,A19,'Test Cases'!$O:$O,"Not Run") -> 0
A20: Cart | B20: =COUNTIF('Test Cases'!$C:$C,A20) -> 2 | C20: =COUNTIFS('Test Cases'!$C:$C,A20,'Test Cases'!$K:$K,"Automated") -> 2 | D20: =COUNTIFS('Test Cases'!$C:$C,A20,'Test Cases'!$O:$O,"Pass") -> 2 | E20: =COUNTIFS('Test Cases'!$C:$C,A20,'Test Cases'!$O:$O,"Fail") -> 0 | F20: =COUNTIFS('Test Cases'!$C:$C,A20,'Test Cases'!$O:$O,"Blocked") -> 0 | G20: =COUNTIFS('Test Cases'!$C:$C,A20,'Test Cases'!$O:$O,"Not Run") -> 0
A21: Checkout | B21: =COUNTIF('Test Cases'!$C:$C,A21) -> 4 | C21: =COUNTIFS('Test Cases'!$C:$C,A21,'Test Cases'!$K:$K,"Automated") -> 4 | D21: =COUNTIFS('Test Cases'!$C:$C,A21,'Test Cases'!$O:$O,"Pass") -> 4 | E21: =COUNTIFS('Test Cases'!$C:$C,A21,'Test Cases'!$O:$O,"Fail") -> 0 | F21: =COUNTIFS('Test Cases'!$C:$C,A21,'Test Cases'!$O:$O,"Blocked") -> 0 | G21: =COUNTIFS('Test Cases'!$C:$C,A21,'Test Cases'!$O:$O,"Not Run") -> 0
A22: End-to-end | B22: =COUNTIF('Test Cases'!$C:$C,A22) -> 1 | C22: =COUNTIFS('Test Cases'!$C:$C,A22,'Test Cases'!$K:$K,"Automated") -> 1 | D22: =COUNTIFS('Test Cases'!$C:$C,A22,'Test Cases'!$O:$O,"Pass") -> 1 | E22: =COUNTIFS('Test Cases'!$C:$C,A22,'Test Cases'!$O:$O,"Fail") -> 0 | F22: =COUNTIFS('Test Cases'!$C:$C,A22,'Test Cases'!$O:$O,"Blocked") -> 0 | G22: =COUNTIFS('Test Cases'!$C:$C,A22,'Test Cases'!$O:$O,"Not Run") -> 0
A23: Users API | B23: =COUNTIF('Test Cases'!$C:$C,A23) -> 4 | C23: =COUNTIFS('Test Cases'!$C:$C,A23,'Test Cases'!$K:$K,"Automated") -> 4 | D23: =COUNTIFS('Test Cases'!$C:$C,A23,'Test Cases'!$O:$O,"Pass") -> 4 | E23: =COUNTIFS('Test Cases'!$C:$C,A23,'Test Cases'!$O:$O,"Fail") -> 0 | F23: =COUNTIFS('Test Cases'!$C:$C,A23,'Test Cases'!$O:$O,"Blocked") -> 0 | G23: =COUNTIFS('Test Cases'!$C:$C,A23,'Test Cases'!$O:$O,"Not Run") -> 0
A24: Total | B24: =SUM(B17:B23) -> 19 | C24: =SUM(C17:C23) -> 19 | D24: =SUM(D17:D23) -> 19 | E24: =SUM(E17:E23) -> 0 | F24: =SUM(F17:F23) -> 0 | G24: =SUM(G17:G23) -> 0
A26: By priority
A27: Priority | B27: Test Cases | C27: Passed | D27: Not Run
A28: Critical | B28: =COUNTIF('Test Cases'!$I:$I,A28) -> 1 | C28: =COUNTIFS('Test Cases'!$I:$I,A28,'Test Cases'!$O:$O,"Pass") -> 1 | D28: =COUNTIFS('Test Cases'!$I:$I,A28,'Test Cases'!$O:$O,"Not Run") -> 0
A29: High | B29: =COUNTIF('Test Cases'!$I:$I,A29) -> 12 | C29: =COUNTIFS('Test Cases'!$I:$I,A29,'Test Cases'!$O:$O,"Pass") -> 12 | D29: =COUNTIFS('Test Cases'!$I:$I,A29,'Test Cases'!$O:$O,"Not Run") -> 0
A30: Medium | B30: =COUNTIF('Test Cases'!$I:$I,A30) -> 4 | C30: =COUNTIFS('Test Cases'!$I:$I,A30,'Test Cases'!$O:$O,"Pass") -> 4 | D30: =COUNTIFS('Test Cases'!$I:$I,A30,'Test Cases'!$O:$O,"Not Run") -> 0
A31: Low | B31: =COUNTIF('Test Cases'!$I:$I,A31) -> 2 | C31: =COUNTIFS('Test Cases'!$I:$I,A31,'Test Cases'!$O:$O,"Pass") -> 2 | D31: =COUNTIFS('Test Cases'!$I:$I,A31,'Test Cases'!$O:$O,"Not Run") -> 0

Sheet Test Scenarios
A1: Scenario ID | B1: Module | C1: Scenario | D1: Description | E1: Priority | F1: Type | G1: Test Cases | H1: Automated | I1: Passed | J1: Status
A2: TS_LOGIN_01 | B2: Login | C2: Valid login | D2: Verify a user can log in with valid credentials and lands on the Products page. | E2: High | F2: Functional - Positive | G2: =COUNTIF('Test Cases'!$B:$B,A2) -> 2 | H2: =COUNTIFS('Test Cases'!$B:$B,A2,'Test Cases'!$K:$K,"Automated") -> 2 | I2: =COUNTIFS('Test Cases'!$B:$B,A2,'Test Cases'!$O:$O,"Pass") -> 2 | J2: =IF(COUNTIFS('Test Cases'!$B:$B,A2,'Test Cases'!$O:$O,"Fail")>0,"Fail",IF(I2=G2,"Pass",IF(I2>0,"Partially passed","Not run"))) -> Pass
A3: TS_LOGIN_02 | B3: Login | C3: Invalid login | D3: Verify login is rejected with an error message for invalid credentials. | E3: High | F3: Negative | G3: =COUNTIF('Test Cases'!$B:$B,A3) -> 2 | H3: =COUNTIFS('Test Cases'!$B:$B,A3,'Test Cases'!$K:$K,"Automated") -> 2 | I3: =COUNTIFS('Test Cases'!$B:$B,A3,'Test Cases'!$O:$O,"Pass") -> 2 | J3: =IF(COUNTIFS('Test Cases'!$B:$B,A3,'Test Cases'!$O:$O,"Fail")>0,"Fail",IF(I3=G3,"Pass",IF(I3>0,"Partially passed","Not run"))) -> Pass
A4: TS_LOGIN_03 | B4: Login | C4: Data-driven login | D4: Verify login using credentials maintained in the Excel test data file. | E4: Medium | F4: Data-driven | G4: =COUNTIF('Test Cases'!$B:$B,A4) -> 1 | H4: =COUNTIFS('Test Cases'!$B:$B,A4,'Test Cases'!$K:$K,"Automated") -> 1 | I4: =COUNTIFS('Test Cases'!$B:$B,A4,'Test Cases'!$O:$O,"Pass") -> 1 | J4: =IF(COUNTIFS('Test Cases'!$B:$B,A4,'Test Cases'!$O:$O,"Fail")>0,"Fail",IF(I4=G4,"Pass",IF(I4>0,"Partially passed","Not run"))) -> Pass
A5: TS_LOGIN_04 | B5: Login | C5: Locked-out user | D5: Verify a locked-out account cannot log in and sees the locked-out message. | E5: Medium | F5: Negative | G5: =COUNTIF('Test Cases'!$B:$B,A5) -> 1 | H5: =COUNTIFS('Test Cases'!$B:$B,A5,'Test Cases'!$K:$K,"Automated") -> 1 | I5: =COUNTIFS('Test Cases'!$B:$B,A5,'Test Cases'!$O:$O,"Pass") -> 1 | J5: =IF(COUNTIFS('Test Cases'!$B:$B,A5,'Test Cases'!$O:$O,"Fail")>0,"Fail",IF(I5=G5,"Pass",IF(I5>0,"Partially passed","Not run"))) -> Pass
A6: TS_NAV_01 | B6: Browser windows | C6: New tab handling | D6: Verify the session is unaffected after opening, closing and switching back from a new browser tab. | E6: Low | F6: Functional - Positive | G6: =COUNTIF('Test Cases'!$B:$B,A6) -> 1 | H6: =COUNTIFS('Test Cases'!$B:$B,A6,'Test Cases'!$K:$K,"Automated") -> 1 | I6: =COUNTIFS('Test Cases'!$B:$B,A6,'Test Cases'!$O:$O,"Pass") -> 1 | J6: =IF(COUNTIFS('Test Cases'!$B:$B,A6,'Test Cases'!$O:$O,"Fail")>0,"Fail",IF(I6=G6,"Pass",IF(I6>0,"Partially passed","Not run"))) -> Pass
A7: TS_PROD_01 | B7: Products | C7: Product sorting | D7: Verify products can be sorted by price. | E7: Medium | F7: Functional - Positive | G7: =COUNTIF('Test Cases'!$B:$B,A7) -> 1 | H7: =COUNTIFS('Test Cases'!$B:$B,A7,'Test Cases'!$K:$K,"Automated") -> 1 | I7: =COUNTIFS('Test Cases'!$B:$B,A7,'Test Cases'!$O:$O,"Pass") -> 1 | J7: =IF(COUNTIFS('Test Cases'!$B:$B,A7,'Test Cases'!$O:$O,"Fail")>0,"Fail",IF(I7=G7,"Pass",IF(I7>0,"Partially passed","Not run"))) -> Pass
A8: TS_CART_01 | B8: Cart | C8: Add to cart | D8: Verify items added from the Products page appear in the cart and the badge count updates. | E8: High | F8: Functional - Positive | G8: =COUNTIF('Test Cases'!$B:$B,A8) -> 1 | H8: =COUNTIFS('Test Cases'!$B:$B,A8,'Test Cases'!$K:$K,"Automated") -> 1 | I8: =COUNTIFS('Test Cases'!$B:$B,A8,'Test Cases'!$O:$O,"Pass") -> 1 | J8: =IF(COUNTIFS('Test Cases'!$B:$B,A8,'Test Cases'!$O:$O,"Fail")>0,"Fail",IF(I8=G8,"Pass",IF(I8>0,"Partially passed","Not run"))) -> Pass
A9: TS_CART_02 | B9: Cart | C9: Remove from cart | D9: Verify items can be removed from the cart and the badge count updates. | E9: Medium | F9: Functional - Positive | G9: =COUNTIF('Test Cases'!$B:$B,A9) -> 1 | H9: =COUNTIFS('Test Cases'!$B:$B,A9,'Test Cases'!$K:$K,"Automated") -> 1 | I9: =COUNTIFS('Test Cases'!$B:$B,A9,'Test Cases'!$O:$O,"Pass") -> 1 | J9: =IF(COUNTIFS('Test Cases'!$B:$B,A9,'Test Cases'!$O:$O,"Fail")>0,"Fail",IF(I9=G9,"Pass",IF(I9>0,"Partially passed","Not run"))) -> Pass
A10: TS_CHK_01 | B10: Checkout | C10: Checkout form validation | D10: Verify the checkout information form rejects missing required fields with the correct error. | E10: High | F10: Negative | G10: =COUNTIF('Test Cases'!$B:$B,A10) -> 3 | H10: =COUNTIFS('Test Cases'!$B:$B,A10,'Test Cases'!$K:$K,"Automated") -> 3 | I10: =COUNTIFS('Test Cases'!$B:$B,A10,'Test Cases'!$O:$O,"Pass") -> 3 | J10: =IF(COUNTIFS('Test Cases'!$B:$B,A10,'Test Cases'!$O:$O,"Fail")>0,"Fail",IF(I10=G10,"Pass",IF(I10>0,"Partially passed","Not run"))) -> Pass
A11: TS_CHK_02 | B11: Checkout | C11: Cancel checkout | D11: Verify cancelling checkout returns the user to the cart with items kept. | E11: Low | F11: Functional - Positive | G11: =COUNTIF('Test Cases'!$B:$B,A11) -> 1 | H11: =COUNTIFS('Test Cases'!$B:$B,A11,'Test Cases'!$K:$K,"Automated") -> 1 | I11: =COUNTIFS('Test Cases'!$B:$B,A11,'Test Cases'!$O:$O,"Pass") -> 1 | J11: =IF(COUNTIFS('Test Cases'!$B:$B,A11,'Test Cases'!$O:$O,"Fail")>0,"Fail",IF(I11=G11,"Pass",IF(I11>0,"Partially passed","Not run"))) -> Pass
A12: TS_E2E_01 | B12: End-to-end | C12: Complete purchase journey | D12: Verify a user can log in, add items, check out with correct totals, complete the order and log out. | E12: Critical | F12: End-to-end | G12: =COUNTIF('Test Cases'!$B:$B,A12) -> 1 | H12: =COUNTIFS('Test Cases'!$B:$B,A12,'Test Cases'!$K:$K,"Automated") -> 1 | I12: =COUNTIFS('Test Cases'!$B:$B,A12,'Test Cases'!$O:$O,"Pass") -> 1 | J12: =IF(COUNTIFS('Test Cases'!$B:$B,A12,'Test Cases'!$O:$O,"Fail")>0,"Fail",IF(I12=G12,"Pass",IF(I12>0,"Partially passed","Not run"))) -> Pass
A13: TS_API_01 | B13: Users API | C13: Retrieve users | D13: Verify single-user and paginated user list endpoints return the expected data. | E13: High | F13: API | G13: =COUNTIF('Test Cases'!$B:$B,A13) -> 2 | H13: =COUNTIFS('Test Cases'!$B:$B,A13,'Test Cases'!$K:$K,"Automated") -> 2 | I13: =COUNTIFS('Test Cases'!$B:$B,A13,'Test Cases'!$O:$O,"Pass") -> 2 | J13: =IF(COUNTIFS('Test Cases'!$B:$B,A13,'Test Cases'!$O:$O,"Fail")>0,"Fail",IF(I13=G13,"Pass",IF(I13>0,"Partially passed","Not run"))) -> Pass
... A15: TS_API_03 | B15: Users API | C15: Unknown user | D15: Verify requesting a non-existent user returns 404. | E15: Medium | F15: API - Negative | G15: =COUNTIF('Test Cases'!$B:$B,A15) -> 1 | H15: =COUNTIFS('Test Cases'!$B:$B,A15,'Test Cases'!$K:$K,"Automated") -> 1 | I15: =COUNTIFS('Test Cases'!$B:$B,A15,'Test Cases'!$O:$O,"Pass") -> 1 | J15: =IF(COUNTIFS('Test Cases'!$B:$B,A15,'Test Cases'!$O:$O,"Fail")>0,"Fail",IF(I15=G15,"Pass",IF(I15>0,"Partially passed","Not run"))) -> Pass

Sheet Test Cases
A1: Test Case ID | B1: Scenario ID | C1: Module | D1: Title | E1: Preconditions | F1: Test Data | G1: Test Steps | H1: Expected Result | I1: Priority | J1: Type | K1: Automation Status | L1: Feature File | M1: Tags | N1: Last Run Date | O1: Last Run Result | P1: Executed By | Q1: Actual Result / Remarks | R1: Defect ID
A2: LOGIN_TC_001 | B2: TS_LOGIN_03 | C2: Login | D2: Login with Excel test data | E2: Login page is reachable. TestData.xlsx contains row LOGIN_001. | F2: TestData.xlsx > Login > TestDataId LOGIN_001 (standard_user / secret_sauce) | G2: 1. Open the login page. 2. Read the credentials for LOGIN_001 from the Excel file. 3. Enter the username and password and click Login. | H2: Products page is displayed. | I2: High | J2: Data-driven | K2: Automated | L2: login/Login.feature | M2: @Browser @smoke @dataDriven | N2: 2026-10-12 | O2: Pass | P2: Automation (mvn clean test -Denv=qa) | Q2: As expected
A3: LOGIN_TC_002 | B3: TS_LOGIN_01 | C3: Login | D3: Login with valid credentials | E3: Login page is reachable. | F3: Username: standard_user Password: secret_sauce | G3: 1. Open the login page. 2. Enter the username and password. 3. Click Login. | H3: Products page is displayed. | I3: High | J3: Functional - Positive | K3: Automated | L3: login/Login.feature | M3: @Browser @smoke | N3: 2026-10-12 | O3: Pass | P3: Automation (mvn clean test -Denv=qa) | Q3: As expected
A4: LOGIN_OL_001 | B4: TS_LOGIN_01 | C4: Login | D4: Login as standard_user (expected: Passed) | E4: Login page is reachable. | F4: Username: standard_user Password: secret_sauce | G4: 1. Open the login page. 2. Enter the username and password. 3. Click Login. | H4: Login succeeds and the Products page is displayed. | I4: High | J4: Functional - Positive | K4: Automated | L4: login/Login.feature | M4: @Browser @parallel | N4: 2026-10-12 | O4: Pass | P4: Automation (mvn clean test -Denv=qa) | Q4: As expected
A5: LOGIN_OL_002 | B5: TS_LOGIN_02 | C5: Login | D5: Login as manager (expected: Failed) | E5: Login page is reachable. | F5: Username: manager Password: manager456 | G5: 1. Open the login page. 2. Enter the username and password. 3. Click Login. | H5: Login is rejected and an error message is shown ("Epic sadface: Username and password do not match any user in this service"). User stays on the login page. | I5: High | J5: Negative | K5: Automated | L5: login/Login.feature | M5: @Browser @parallel | N5: 2026-10-12 | O5: Pass | P5: Automation (mvn clean test -Denv=qa) | Q5: As expected
A6: LOGIN_OL_003 | B6: TS_LOGIN_02 | C6: Login | D6: Login as employee (expected: Failed) | E6: Login page is reachable. | F6: Username: employee Password: employee789 | G6: 1. Open the login page. 2. Enter the username and password. 3. Click Login. | H6: Login is rejected and an error message is shown. User stays on the login page. | I6: High | J6: Negative | K6: Automated | L6: login/Login.feature | M6: @Browser @parallel | N6: 2026-10-12 | O6: Pass | P6: Automation (mvn clean test -Denv=qa) | Q6: As expected
A7: LOGIN_TC_003 | B7: TS_NAV_01 | C7: Browser windows | D7: Open and close a new tab after login | E7: User can log in with LOGIN_001 test data. | F7: TestDataId LOGIN_001 URL: https://www.google.com/ | G7: 1. Log in using test data LOGIN_001. 2. Verify the Products page is displayed. 3. Open a new tab and go to https://www.google.com/. 4. Close the current tab. 5. Switch back to the original window. | H7: After switching back, the Products page is still displayed and the user is still logged in. | I7: Low | J7: Functional - Positive | K7: Automated | L7: login/Login.feature | M7: @Browser @switchwindowtest | N7: 2026-10-12 | O7: Pass | P7: Automation (mvn clean test -Denv=qa) | Q7: As expected
A8: LOGIN_TC_004 | B8: TS_LOGIN_04 | C8: Login | D8: Login as locked-out user | E8: Login page is reachable. | F8: Username: locked_out_user Password: secret_sauce | G8: 1. Open the login page. 2. Enter the username and password. 3. Click Login. | H8: Login is rejected with "Epic sadface: Sorry, this user has been locked out." User stays on the login page. | I8: Medium | J8: Negative | K8: Automated | L8: login/Login.feature | M8: @Browser @locked_out | N8: 2026-10-12 | O8: Pass | P8: Automation (mvn clean test -Denv=qa) | Q8: As expected
A9: PROD_TC_001 | B9: TS_PROD_01 | C9: Products | D9: Sort products by price (low to high) | E9: User is logged in as standard_user. | F9: Sort option: Price (low to high) | G9: 1. On the Products page, open the sort drop-down. 2. Select 'Price (low to high)'. | H9: Products are listed in ascending order of price. | I9: Medium | J9: Functional - Positive | K9: Automated | L9: products/Products.feature | M9: @Browser @Regression @sorting | N9: 2026-10-12 | O9: Pass | P9: Automation (mvn clean test -Denv=qa) | Q9: As expected
A10: CART_TC_001 | B10: TS_CART_01 | C10: Cart | D10: Add an item to the cart | E10: User can log in with LOGIN_001 test data. | F10: Item: Sauce Labs Backpack | G10: 1. Log in using test data LOGIN_001. 2. Click 'Add to cart' for Sauce Labs Backpack. 3. Check the cart badge. 4. Open the cart. | H10: Cart badge shows 1. Cart page is displayed and contains Sauce Labs Backpack. | I10: High | J10: Functional - Positive | K10: Automated | L10: cart/Cart.feature | M10: @Browser @Regression @smoke @add_to_cart | N10: 2026-10-12 | O10: Pass | P10: Automation (mvn clean test -Denv=qa) | Q10: As expected
A11: CART_TC_002 | B11: TS_CART_02 | C11: Cart | D11: Remove an item from the cart | E11: User is logged in as standard_user. | F11: Item: Sauce Labs Backpack | G11: 1. Log in as standard_user. 2. Add Sauce Labs Backpack to the cart. 3. Open the cart and confirm the item is listed. 4. Click 'Remove' for Sauce Labs Backpack. | H11: Item is removed from the cart list and the cart badge is no longer shown. | I11: Medium | J11: Functional - Positive | K11: Automated | L11: cart/Cart.feature | M11: @Browser @Regression @remove_from_cart | N11: 2026-10-12 | O11: Pass | P11: Automation (mvn clean test -Denv=qa) | Q11: As expected
A12: CHECKOUT_TC_001 | B12: TS_CHK_01 | C12: Checkout | D12: Checkout requires first name | E12: User is logged in as standard_user with Sauce Labs Backpack in the cart, on checkout step one. | F12: First name: (empty) Last name: Doe Postal code: 12345 | G12: 1. Leave First Name empty, enter Last Name and Postal Code. 2. Click Continue. | H12: Error "Error: First Name is required" is displayed and the user stays on the form. | I12: High | J12: Negative | K12: Automated | L12: checkout/CheckoutValidation.feature | M12: @Browser @Regression @checkout_validation | N12: 2026-10-12 | O12: Pass | P12: Automation (mvn clean test -Denv=qa) | Q12: As expected
A13: CHECKOUT_TC_002 | B13: TS_CHK_01 | C13: Checkout | D13: Checkout requires last name | E13: Same as CHECKOUT_TC_001. | F13: First name: John Last name: (empty) Postal code: 12345 | G13: 1. Enter First Name and Postal Code, leave Last Name empty. 2. Click Continue. | H13: Error "Error: Last Name is required" is displayed and the user stays on the form. | I13: High | J13: Negative | K13: Automated | L13: checkout/CheckoutValidation.feature | M13: @Browser @Regression @checkout_validation | N13: 2026-10-12 | O13: Pass | P13: Automation (mvn clean test -Denv=qa) | Q13: As expected
... A20: API_TC_004 | B20: TS_API_03 | C20: Users API | D20: Get a user that does not exist | E20: reqres.in is reachable. | F20: GET /users/23 | G20: 1. Send GET request to /users/23. | H20: Status 404. Response body is an empty JSON object ({}). | I20: Medium | J20: API - Negative | K20: Automated | L20: api/API.feature | M20: @API @get_unknown_user | N20: 2026-10-12 | O20: Pass | P20: Automation (mvn clean test -Denv=qa) | Q20: As expected
